2025-04-18 13:24:47,944 - Threaded polling exception: A request to the Telegram API was unsuccessful. Error code: 429. Description: Too Many Requests: retry after 40
2025-04-18 13:24:47,946 - Exception traceback:
Traceback (most recent call last):
  File "/home/master/.local/lib/python3.11/site-packages/telebot/__init__.py", line 1235, in __threaded_polling
    self.worker_pool.raise_exceptions()
  File "/home/master/.local/lib/python3.11/site-packages/telebot/util.py", line 150, in raise_exceptions
    raise self.exception_info
  File "/home/master/.local/lib/python3.11/site-packages/telebot/util.py", line 93, in run
    task(*args, **kwargs)
  File "/home/master/.local/lib/python3.11/site-packages/telebot/__init__.py", line 9233, in _run_middlewares_and_handler
    result = handler['function'](message)
             ^^^^^^^^^^^^^^^^^^^^^^^^^^^^
  File "/home/master/rohit/x9.py", line 275, in show_status
    bot.reply_to(message, UNAUTHORIZED_MESSAGE)
  File "/home/master/.local/lib/python3.11/site-packages/telebot/__init__.py", line 5949, in reply_to
    return self.send_message(message.chat.id, text, reply_parameters=reply_parameters, **kwargs)
           ^^^^^^^^^^^^^^^^^^^^^^^^^^^^^^^^^^^^^^^^^^^^^^^^^^^^^^^^^^^^^^^^^^^^^^^^^^^^^^^^^^^^^
  File "/home/master/.local/lib/python3.11/site-packages/telebot/__init__.py", line 1800, in send_message
    apihelper.send_message(
  File "/home/master/.local/lib/python3.11/site-packages/telebot/apihelper.py", line 275, in send_message
    return _make_request(token, method_url, params=payload, method='post')
           ^^^^^^^^^^^^^^^^^^^^^^^^^^^^^^^^^^^^^^^^^^^^^^^^^^^^^^^^^^^^^^^
  File "/home/master/.local/lib/python3.11/site-packages/telebot/apihelper.py", line 168, in _make_request
    json_result = _check_result(method_name, result)
                  ^^^^^^^^^^^^^^^^^^^^^^^^^^^^^^^^^^
  File "/home/master/.local/lib/python3.11/site-packages/telebot/apihelper.py", line 195, in _check_result
    raise ApiTelegramException(method_name, result, result_json)
telebot.apihelper.ApiTelegramException: A request to the Telegram API was unsuccessful. Error code: 429. Description: Too Many Requests: retry after 40

2025-04-18 13:24:48,324 - Threaded polling exception: A request to the Telegram API was unsuccessful. Error code: 429. Description: Too Many Requests: retry after 39
2025-04-18 13:24:48,325 - Exception traceback:
Traceback (most recent call last):
  File "/home/master/.local/lib/python3.11/site-packages/telebot/__init__.py", line 1235, in __threaded_polling
    self.worker_pool.raise_exceptions()
  File "/home/master/.local/lib/python3.11/site-packages/telebot/util.py", line 150, in raise_exceptions
    raise self.exception_info
  File "/home/master/.local/lib/python3.11/site-packages/telebot/util.py", line 93, in run
    task(*args, **kwargs)
  File "/home/master/.local/lib/python3.11/site-packages/telebot/__init__.py", line 9233, in _run_middlewares_and_handler
    result = handler['function'](message)
             ^^^^^^^^^^^^^^^^^^^^^^^^^^^^
  File "/home/master/rohit/x9.py", line 98, in start_command
    bot.reply_to(message, UNAUTHORIZED_MESSAGE)
  File "/home/master/.local/lib/python3.11/site-packages/telebot/__init__.py", line 5949, in reply_to
    return self.send_message(message.chat.id, text, reply_parameters=reply_parameters, **kwargs)
           ^^^^^^^^^^^^^^^^^^^^^^^^^^^^^^^^^^^^^^^^^^^^^^^^^^^^^^^^^^^^^^^^^^^^^^^^^^^^^^^^^^^^^
  File "/home/master/.local/lib/python3.11/site-packages/telebot/__init__.py", line 1800, in send_message
    apihelper.send_message(
  File "/home/master/.local/lib/python3.11/site-packages/telebot/apihelper.py", line 275, in send_message
    return _make_request(token, method_url, params=payload, method='post')
           ^^^^^^^^^^^^^^^^^^^^^^^^^^^^^^^^^^^^^^^^^^^^^^^^^^^^^^^^^^^^^^^
  File "/home/master/.local/lib/python3.11/site-packages/telebot/apihelper.py", line 168, in _make_request
    json_result = _check_result(method_name, result)
                  ^^^^^^^^^^^^^^^^^^^^^^^^^^^^^^^^^^
  File "/home/master/.local/lib/python3.11/site-packages/telebot/apihelper.py", line 195, in _check_result
    raise ApiTelegramException(method_name, result, result_json)
telebot.apihelper.ApiTelegramException: A request to the Telegram API was unsuccessful. Error code: 429. Description: Too Many Requests: retry after 39

2025-04-18 13:24:49,079 - Threaded polling exception: A request to the Telegram API was unsuccessful. Error code: 429. Description: Too Many Requests: retry after 39
2025-04-18 13:24:49,083 - Exception traceback:
Traceback (most recent call last):
  File "/home/master/.local/lib/python3.11/site-packages/telebot/__init__.py", line 1235, in __threaded_polling
    self.worker_pool.raise_exceptions()
  File "/home/master/.local/lib/python3.11/site-packages/telebot/util.py", line 150, in raise_exceptions
    raise self.exception_info
  File "/home/master/.local/lib/python3.11/site-packages/telebot/util.py", line 93, in run
    task(*args, **kwargs)
  File "/home/master/.local/lib/python3.11/site-packages/telebot/__init__.py", line 9233, in _run_middlewares_and_handler
    result = handler['function'](message)
             ^^^^^^^^^^^^^^^^^^^^^^^^^^^^
  File "/home/master/rohit/x9.py", line 118, in add_user
    bot.reply_to(message, response)
  File "/home/master/.local/lib/python3.11/site-packages/telebot/__init__.py", line 5949, in reply_to
    return self.send_message(message.chat.id, text, reply_parameters=reply_parameters, **kwargs)
           ^^^^^^^^^^^^^^^^^^^^^^^^^^^^^^^^^^^^^^^^^^^^^^^^^^^^^^^^^^^^^^^^^^^^^^^^^^^^^^^^^^^^^
  File "/home/master/.local/lib/python3.11/site-packages/telebot/__init__.py", line 1800, in send_message
    apihelper.send_message(
  File "/home/master/.local/lib/python3.11/site-packages/telebot/apihelper.py", line 275, in send_message
    return _make_request(token, method_url, params=payload, method='post')
           ^^^^^^^^^^^^^^^^^^^^^^^^^^^^^^^^^^^^^^^^^^^^^^^^^^^^^^^^^^^^^^^
  File "/home/master/.local/lib/python3.11/site-packages/telebot/apihelper.py", line 168, in _make_request
    json_result = _check_result(method_name, result)
                  ^^^^^^^^^^^^^^^^^^^^^^^^^^^^^^^^^^
  File "/home/master/.local/lib/python3.11/site-packages/telebot/apihelper.py", line 195, in _check_result
    raise ApiTelegramException(method_name, result, result_json)
telebot.apihelper.ApiTelegramException: A request to the Telegram API was unsuccessful. Error code: 429. Description: Too Many Requests: retry after 39

2025-04-18 13:24:50,203 - Threaded polling exception: A request to the Telegram API was unsuccessful. Error code: 429. Description: Too Many Requests: retry after 37
2025-04-18 13:24:50,204 - Exception traceback:
Traceback (most recent call last):
  File "/home/master/.local/lib/python3.11/site-packages/telebot/__init__.py", line 1235, in __threaded_polling
    self.worker_pool.raise_exceptions()
  File "/home/master/.local/lib/python3.11/site-packages/telebot/util.py", line 150, in raise_exceptions
    raise self.exception_info
  File "/home/master/.local/lib/python3.11/site-packages/telebot/util.py", line 93, in run
    task(*args, **kwargs)
  File "/home/master/.local/lib/python3.11/site-packages/telebot/__init__.py", line 9233, in _run_middlewares_and_handler
    result = handler['function'](message)
             ^^^^^^^^^^^^^^^^^^^^^^^^^^^^
  File "/home/master/rohit/x9.py", line 98, in start_command
    bot.reply_to(message, UNAUTHORIZED_MESSAGE)
  File "/home/master/.local/lib/python3.11/site-packages/telebot/__init__.py", line 5949, in reply_to
    return self.send_message(message.chat.id, text, reply_parameters=reply_parameters, **kwargs)
           ^^^^^^^^^^^^^^^^^^^^^^^^^^^^^^^^^^^^^^^^^^^^^^^^^^^^^^^^^^^^^^^^^^^^^^^^^^^^^^^^^^^^^
  File "/home/master/.local/lib/python3.11/site-packages/telebot/__init__.py", line 1800, in send_message
    apihelper.send_message(
  File "/home/master/.local/lib/python3.11/site-packages/telebot/apihelper.py", line 275, in send_message
    return _make_request(token, method_url, params=payload, method='post')
           ^^^^^^^^^^^^^^^^^^^^^^^^^^^^^^^^^^^^^^^^^^^^^^^^^^^^^^^^^^^^^^^
  File "/home/master/.local/lib/python3.11/site-packages/telebot/apihelper.py", line 168, in _make_request
    json_result = _check_result(method_name, result)
                  ^^^^^^^^^^^^^^^^^^^^^^^^^^^^^^^^^^
  File "/home/master/.local/lib/python3.11/site-packages/telebot/apihelper.py", line 195, in _check_result
    raise ApiTelegramException(method_name, result, result_json)
telebot.apihelper.ApiTelegramException: A request to the Telegram API was unsuccessful. Error code: 429. Description: Too Many Requests: retry after 37

2025-04-18 13:24:52,290 - Threaded polling exception: A request to the Telegram API was unsuccessful. Error code: 429. Description: Too Many Requests: retry after 35
2025-04-18 13:24:52,291 - Exception traceback:
Traceback (most recent call last):
  File "/home/master/.local/lib/python3.11/site-packages/telebot/__init__.py", line 1235, in __threaded_polling
    self.worker_pool.raise_exceptions()
  File "/home/master/.local/lib/python3.11/site-packages/telebot/util.py", line 150, in raise_exceptions
    raise self.exception_info
  File "/home/master/.local/lib/python3.11/site-packages/telebot/util.py", line 93, in run
    task(*args, **kwargs)
  File "/home/master/.local/lib/python3.11/site-packages/telebot/__init__.py", line 9233, in _run_middlewares_and_handler
    result = handler['function'](message)
             ^^^^^^^^^^^^^^^^^^^^^^^^^^^^
  File "/home/master/rohit/x9.py", line 247, in handle_attack
    bot.reply_to(message, UNAUTHORIZED_MESSAGE)
  File "/home/master/.local/lib/python3.11/site-packages/telebot/__init__.py", line 5949, in reply_to
    return self.send_message(message.chat.id, text, reply_parameters=reply_parameters, **kwargs)
           ^^^^^^^^^^^^^^^^^^^^^^^^^^^^^^^^^^^^^^^^^^^^^^^^^^^^^^^^^^^^^^^^^^^^^^^^^^^^^^^^^^^^^
  File "/home/master/.local/lib/python3.11/site-packages/telebot/__init__.py", line 1800, in send_message
    apihelper.send_message(
  File "/home/master/.local/lib/python3.11/site-packages/telebot/apihelper.py", line 275, in send_message
    return _make_request(token, method_url, params=payload, method='post')
           ^^^^^^^^^^^^^^^^^^^^^^^^^^^^^^^^^^^^^^^^^^^^^^^^^^^^^^^^^^^^^^^
  File "/home/master/.local/lib/python3.11/site-packages/telebot/apihelper.py", line 168, in _make_request
    json_result = _check_result(method_name, result)
                  ^^^^^^^^^^^^^^^^^^^^^^^^^^^^^^^^^^
  File "/home/master/.local/lib/python3.11/site-packages/telebot/apihelper.py", line 195, in _check_result
    raise ApiTelegramException(method_name, result, result_json)
telebot.apihelper.ApiTelegramException: A request to the Telegram API was unsuccessful. Error code: 429. Description: Too Many Requests: retry after 35

